[2025-08-02T00:02:12.113+0000] {local_task_job_runner.py:120} INFO - ::group::Pre task execution logs
[2025-08-02T00:02:12.191+0000] {taskinstance.py:2073} INFO - Dependencies all met for dep_context=non-requeueable deps ti=<TaskInstance: pokemon_etl_dag.extract_data scheduled__2025-08-01T00:00:00+00:00 [queued]>
[2025-08-02T00:02:12.207+0000] {taskinstance.py:2073} INFO - Dependencies all met for dep_context=requeueable deps ti=<TaskInstance: pokemon_etl_dag.extract_data scheduled__2025-08-01T00:00:00+00:00 [queued]>
[2025-08-02T00:02:12.210+0000] {taskinstance.py:2303} INFO - Starting attempt 2 of 2
[2025-08-02T00:02:12.236+0000] {taskinstance.py:2327} INFO - Executing <Task(PythonOperator): extract_data> on 2025-08-01 00:00:00+00:00
[2025-08-02T00:02:12.257+0000] {standard_task_runner.py:63} INFO - Started process 559 to run task
[2025-08-02T00:02:12.263+0000] {standard_task_runner.py:90} INFO - Running: ['***', 'tasks', 'run', 'pokemon_etl_dag', 'extract_data', 'scheduled__2025-08-01T00:00:00+00:00', '--job-id', '37', '--raw', '--subdir', 'DAGS_FOLDER/pokemon_dags.py', '--cfg-path', '/tmp/tmp4hmsq_38']
[2025-08-02T00:02:12.270+0000] {standard_task_runner.py:91} INFO - Job 37: Subtask extract_data
[2025-08-02T00:02:12.311+0000] {logging_mixin.py:188} WARNING - /home/***/.local/lib/python3.11/site-packages/***/settings.py:195 DeprecationWarning: The sql_alchemy_conn option in [core] has been moved to the sql_alchemy_conn option in [database] - the old setting has been used, but please update your config.
[2025-08-02T00:02:12.421+0000] {task_command.py:426} INFO - Running <TaskInstance: pokemon_etl_dag.extract_data scheduled__2025-08-01T00:00:00+00:00 [running]> on host 67c618456cf9
[2025-08-02T00:02:12.611+0000] {taskinstance.py:2644} INFO - Exporting env vars: AIRFLOW_CTX_DAG_OWNER='Luis' AIRFLOW_CTX_DAG_ID='pokemon_etl_dag' AIRFLOW_CTX_TASK_ID='extract_data' AIRFLOW_CTX_EXECUTION_DATE='2025-08-01T00:00:00+00:00' AIRFLOW_CTX_TRY_NUMBER='2' AIRFLOW_CTX_DAG_RUN_ID='scheduled__2025-08-01T00:00:00+00:00'
[2025-08-02T00:02:12.617+0000] {taskinstance.py:430} INFO - ::endgroup::
[2025-08-02T00:02:12.645+0000] {extract.py:92} INFO - Obteniendo lista de generaciones...
[2025-08-02T00:02:12.650+0000] {taskinstance.py:441} INFO - ::group::Post task execution logs
[2025-08-02T00:02:12.652+0000] {taskinstance.py:2890} ERROR - Task failed with exception
Traceback (most recent call last):
  File "/home/airflow/.local/lib/python3.11/site-packages/airflow/models/taskinstance.py", line 465, in _execute_task
    result = _execute_callable(context=context, **execute_callable_kwargs)
             ^^^^^^^^^^^^^^^^^^^^^^^^^^^^^^^^^^^^^^^^^^^^^^^^^^^^^^^^^^^^^
  File "/home/airflow/.local/lib/python3.11/site-packages/airflow/models/taskinstance.py", line 432, in _execute_callable
    return execute_callable(context=context, **execute_callable_kwargs)
           ^^^^^^^^^^^^^^^^^^^^^^^^^^^^^^^^^^^^^^^^^^^^^^^^^^^^^^^^^^^^
  File "/home/airflow/.local/lib/python3.11/site-packages/airflow/models/baseoperator.py", line 400, in wrapper
    return func(self, *args, **kwargs)
           ^^^^^^^^^^^^^^^^^^^^^^^^^^^
  File "/home/airflow/.local/lib/python3.11/site-packages/airflow/operators/python.py", line 235, in execute
    return_value = self.execute_callable()
                   ^^^^^^^^^^^^^^^^^^^^^^^
  File "/home/airflow/.local/lib/python3.11/site-packages/airflow/operators/python.py", line 252, in execute_callable
    return self.python_callable(*self.op_args, **self.op_kwargs)
           ^^^^^^^^^^^^^^^^^^^^^^^^^^^^^^^^^^^^^^^^^^^^^^^^^^^^^
  File "/opt/airflow/dags/pokemon_dags.py", line 53, in extract_data
    asyncio.run(get_raw_species(raw_species_path, api_base_url, generations))
  File "/usr/local/lib/python3.11/asyncio/runners.py", line 190, in run
    return runner.run(main)
           ^^^^^^^^^^^^^^^^
  File "/usr/local/lib/python3.11/asyncio/runners.py", line 118, in run
    return self._loop.run_until_complete(task)
           ^^^^^^^^^^^^^^^^^^^^^^^^^^^^^^^^^^^
  File "/usr/local/lib/python3.11/asyncio/base_events.py", line 654, in run_until_complete
    return future.result()
           ^^^^^^^^^^^^^^^
  File "/opt/airflow/src/pokemon_etl/extract.py", line 93, in get_raw_species
    generations = await get_pokemon_gens(session, base_url, generation_list)
                  ^^^^^^^^^^^^^^^^^^^^^^^^^^^^^^^^^^^^^^^^^^^^^^^^^^^^^^^^^^
  File "/opt/airflow/src/pokemon_etl/extract.py", line 31, in get_pokemon_gens
    data = await fetch(session, url)
           ^^^^^^^^^^^^^^^^^^^^^^^^^
  File "/opt/airflow/src/pokemon_etl/extract.py", line 14, in fetch
    async with session.get(url) as response:
  File "/home/airflow/.local/lib/python3.11/site-packages/aiohttp/client.py", line 1194, in __aenter__
    self._resp = await self._coro
                 ^^^^^^^^^^^^^^^^
  File "/home/airflow/.local/lib/python3.11/site-packages/aiohttp/client.py", line 545, in _request
    req = self._request_class(
          ^^^^^^^^^^^^^^^^^^^^
  File "/home/airflow/.local/lib/python3.11/site-packages/aiohttp/client_reqrep.py", line 326, in __init__
    self.update_host(url)
  File "/home/airflow/.local/lib/python3.11/site-packages/aiohttp/client_reqrep.py", line 400, in update_host
    raise InvalidURL(url)
aiohttp.client_exceptions.InvalidURL: %22https://pokeapi.co/api/v2/%22generation/
[2025-08-02T00:02:12.700+0000] {taskinstance.py:1205} INFO - Marking task as FAILED. dag_id=pokemon_etl_dag, task_id=extract_data, execution_date=20250801T000000, start_date=20250802T000212, end_date=20250802T000212
[2025-08-02T00:02:12.720+0000] {standard_task_runner.py:110} ERROR - Failed to execute job 37 for task extract_data (%22https://pokeapi.co/api/v2/%22generation/; 559)
[2025-08-02T00:02:12.764+0000] {local_task_job_runner.py:240} INFO - Task exited with return code 1
[2025-08-02T00:02:12.804+0000] {taskinstance.py:3482} INFO - 0 downstream tasks scheduled from follow-on schedule check
[2025-08-02T00:02:12.813+0000] {local_task_job_runner.py:222} INFO - ::endgroup::
