[2025-07-31T23:04:49.440+0000] {local_task_job_runner.py:120} INFO - ::group::Pre task execution logs
[2025-07-31T23:04:49.520+0000] {taskinstance.py:2073} INFO - Dependencies all met for dep_context=non-requeueable deps ti=<TaskInstance: pokemon_etl_dag.load_data manual__2025-07-31T23:01:19.107911+00:00 [queued]>
[2025-07-31T23:04:49.543+0000] {taskinstance.py:2073} INFO - Dependencies all met for dep_context=requeueable deps ti=<TaskInstance: pokemon_etl_dag.load_data manual__2025-07-31T23:01:19.107911+00:00 [queued]>
[2025-07-31T23:04:49.547+0000] {taskinstance.py:2303} INFO - Starting attempt 2 of 2
[2025-07-31T23:04:49.582+0000] {taskinstance.py:2327} INFO - Executing <Task(PythonOperator): load_data> on 2025-07-31 23:01:19.107911+00:00
[2025-07-31T23:04:49.606+0000] {standard_task_runner.py:63} INFO - Started process 450 to run task
[2025-07-31T23:04:49.615+0000] {standard_task_runner.py:90} INFO - Running: ['***', 'tasks', 'run', 'pokemon_etl_dag', 'load_data', 'manual__2025-07-31T23:01:19.107911+00:00', '--job-id', '28', '--raw', '--subdir', 'DAGS_FOLDER/pokemon_dags.py', '--cfg-path', '/tmp/tmpij3kfotw']
[2025-07-31T23:04:49.624+0000] {standard_task_runner.py:91} INFO - Job 28: Subtask load_data
[2025-07-31T23:04:49.679+0000] {logging_mixin.py:188} WARNING - /home/***/.local/lib/python3.11/site-packages/***/settings.py:195 DeprecationWarning: The sql_alchemy_conn option in [core] has been moved to the sql_alchemy_conn option in [database] - the old setting has been used, but please update your config.
[2025-07-31T23:04:49.854+0000] {task_command.py:426} INFO - Running <TaskInstance: pokemon_etl_dag.load_data manual__2025-07-31T23:01:19.107911+00:00 [running]> on host 79dd1729ef10
[2025-07-31T23:04:50.151+0000] {taskinstance.py:2644} INFO - Exporting env vars: AIRFLOW_CTX_DAG_OWNER='Luis' AIRFLOW_CTX_DAG_ID='pokemon_etl_dag' AIRFLOW_CTX_TASK_ID='load_data' AIRFLOW_CTX_EXECUTION_DATE='2025-07-31T23:01:19.107911+00:00' AIRFLOW_CTX_TRY_NUMBER='2' AIRFLOW_CTX_DAG_RUN_ID='manual__2025-07-31T23:01:19.107911+00:00'
[2025-07-31T23:04:50.154+0000] {taskinstance.py:430} INFO - ::endgroup::
[2025-07-31T23:04:50.343+0000] {load.py:39} INFO - Datos de Pokémon leídos exitosamente desde Parquet.
[2025-07-31T23:04:50.344+0000] {load.py:19} INFO - Intentando conectar a la base de datos PostgreSQL...
[2025-07-31T23:04:50.373+0000] {load.py:28} INFO - Error al conectar a la base de datos: (psycopg2.OperationalError) connection to server at "pokemon-db" (172.18.0.3), port 5432 failed: FATAL:  password authentication failed for user "myuser"

(Background on this error at: https://sqlalche.me/e/14/e3q8)
[2025-07-31T23:04:50.379+0000] {load.py:64} ERROR - Error al cargar los datos de Pokémon en la base de datos: 'NoneType' object has no attribute 'connect'
[2025-07-31T23:04:50.381+0000] {taskinstance.py:441} INFO - ::group::Post task execution logs
[2025-07-31T23:04:50.383+0000] {taskinstance.py:2890} ERROR - Task failed with exception
Traceback (most recent call last):
  File "/home/airflow/.local/lib/python3.11/site-packages/airflow/models/taskinstance.py", line 465, in _execute_task
    result = _execute_callable(context=context, **execute_callable_kwargs)
             ^^^^^^^^^^^^^^^^^^^^^^^^^^^^^^^^^^^^^^^^^^^^^^^^^^^^^^^^^^^^^
  File "/home/airflow/.local/lib/python3.11/site-packages/airflow/models/taskinstance.py", line 432, in _execute_callable
    return execute_callable(context=context, **execute_callable_kwargs)
           ^^^^^^^^^^^^^^^^^^^^^^^^^^^^^^^^^^^^^^^^^^^^^^^^^^^^^^^^^^^^
  File "/home/airflow/.local/lib/python3.11/site-packages/airflow/models/baseoperator.py", line 400, in wrapper
    return func(self, *args, **kwargs)
           ^^^^^^^^^^^^^^^^^^^^^^^^^^^
  File "/home/airflow/.local/lib/python3.11/site-packages/airflow/operators/python.py", line 235, in execute
    return_value = self.execute_callable()
                   ^^^^^^^^^^^^^^^^^^^^^^^
  File "/home/airflow/.local/lib/python3.11/site-packages/airflow/operators/python.py", line 252, in execute_callable
    return self.python_callable(*self.op_args, **self.op_kwargs)
           ^^^^^^^^^^^^^^^^^^^^^^^^^^^^^^^^^^^^^^^^^^^^^^^^^^^^^
  File "/opt/airflow/dags/pokemon_dags.py", line 70, in load_data
    load_pokemons_to_db(
  File "/opt/airflow/src/pokemon_etl/load.py", line 60, in load_pokemons_to_db
    with engine.connect() as conn:
         ^^^^^^^^^^^^^^
AttributeError: 'NoneType' object has no attribute 'connect'
[2025-07-31T23:04:50.442+0000] {taskinstance.py:1205} INFO - Marking task as FAILED. dag_id=pokemon_etl_dag, task_id=load_data, execution_date=20250731T230119, start_date=20250731T230449, end_date=20250731T230450
[2025-07-31T23:04:50.476+0000] {standard_task_runner.py:110} ERROR - Failed to execute job 28 for task load_data ('NoneType' object has no attribute 'connect'; 450)
[2025-07-31T23:04:50.557+0000] {local_task_job_runner.py:240} INFO - Task exited with return code 1
[2025-07-31T23:04:50.608+0000] {taskinstance.py:3482} INFO - 0 downstream tasks scheduled from follow-on schedule check
[2025-07-31T23:04:50.615+0000] {local_task_job_runner.py:222} INFO - ::endgroup::
